Workbook

Sheet 指示書作成シート(成形）
A1: 注 文 書 ／ 納 入 指 示 書 ( 成 形 ）
H8: 株式会社 ヨシダパッケージ
H9: 伝票 / LOT No. | J9: 261803
H11: 発注 / 手配日 | J11: 2026.3.6
A14: 下記の通り納入願います。
A15: 尚、納期回答につきましてはREFAXにてお願い致します。
A16: 要求No. | B16: P/N 品 名 | H16: 数 量 | I16: 荷姿 | K16: 納期
B17: SMK-228 | H17: 7 | K17: 3/16 3/17
B18: =VLOOKUP(B17,トレイデータ一覧表!1:1048576,2,FALSE) -> SMK-228 P試作 | I18: =VLOOKUP(B17,トレイデータ一覧表!1:1048576,9,FALSE) -> 0 | J18: =ROUNDDOWN(H17/I18,0) -> #DIV/0!
B19: 材質 | C19: 厚み | D19: 巾 | E19: 帯電 | F19: ｼﾘｺﾝ | G19: 塗布 | I19: =H17-(I18*J18) -> #DIV/0! | J19: =IF(I19>0,"×1"," ") -> #DIV/0!
B20: =VLOOKUP(B17,トレイデータ一覧表!1:1048576,3,FALSE) -> PP(N) | C20: =VLOOKUP(B17,トレイデータ一覧表!1:1048576,4,FALSE) -> 0.8 | D20: =VLOOKUP(B17,トレイデータ一覧表!1:1048576,5,FALSE) -> 520 | E20: =VLOOKUP(B17,トレイデータ一覧表!1:1048576,6,FALSE) -> 有 | F20: =VLOOKUP(B17,トレイデータ一覧表!1:1048576,7,FALSE) -> 無 | G20: =VLOOKUP(B17,トレイデータ一覧表!1:1048576,8,FALSE) -> 無
A23: 要求No. | B23: P/N 品 名 | H23: 数 量 | I23: 荷姿 | K23: 納期
B24: -
B25: =VLOOKUP(B24,トレイデータ一覧表!1:1048576,2,FALSE) -> - | I25: =VLOOKUP(B24,トレイデータ一覧表!1:1048576,9,FALSE) -> - | J25: =ROUNDDOWN(H24/I25,0) -> #VALUE!
B26: 材質 | C26: 厚み | D26: 巾 | E26: 帯電 | F26: ｼﾘｺﾝ | G26: 塗布 | I26: =H24-(I25*J25) -> #VALUE! | J26: =IF(I26>0,"×1"," ") -> #VALUE!
B27: =VLOOKUP(B24,トレイデータ一覧表!1:1048576,3,FALSE) -> - | C27: =VLOOKUP(B24,トレイデータ一覧表!1:1048576,4,FALSE) -> - | D27: =VLOOKUP(B24,トレイデータ一覧表!1:1048576,5,FALSE) -> - | E27: =VLOOKUP(B24,トレイデータ一覧表!1:1048576,6,FALSE) -> - | F27: =VLOOKUP(B24,トレイデータ一覧表!1:1048576,7,FALSE) -> - | G27: =VLOOKUP(B24,トレイデータ一覧表!1:1048576,8,FALSE) -> -
G31: 短手公差
G32: =VLOOKUP(B17,トレイデータ一覧表!1:1048576,20,FALSE) -> 0
G33: =VLOOKUP(B17,トレイデータ一覧表!1:1048576,21,FALSE) -> 0
B34: 長手公差
B35: =VLOOKUP(B17,トレイデータ一覧表!1:1048576,18,FALSE) -> 0
B36: =VLOOKUP(B17,トレイデータ一覧表!1:1048576,19,FALSE) -> 0
H38: CUT LINE
I39: =VLOOKUP(B17,トレイデータ一覧表!1:1048576,22,FALSE) -> 0 | J39: × | K39: =VLOOKUP(B17,トレイデータ一覧表!1:1048576,23,FALSE) -> 0
A42: 納品先: | B42: SMK3 | H42: 依頼元：
A43: =VLOOKUP(B42,納入先一覧表!1:1048576,2,FALSE) -> SMK（株）富山
A44: =VLOOKUP(B42,納入先一覧表!1:1048576,5,FALSE) -> 延澤 様
A45: =VLOOKUP(B42,納入先一覧表!1:1048576,3,FALSE) -> 〒939-2366 富山県富山市八尾町保内1-1 | H45: =VLOOKUP(B42,納入先一覧表!1:1048576,4,FALSE) -> SMK01
A46: ＴＥＬ
A47: =VLOOKUP(B42,納入先一覧表!1:1048576,6,FALSE) -> 076-455-1215
A50: 各部門の担当者は処理後、サイン又は捺印し速やかに次の部門へ配布願います。 | E50: 総務 | G50: 成形 | I50: プレス | K50: 総務

Sheet 指示書作成シート（外注）
A1: 注 文 書 ／ 納 入 指 示 書
H7: 株式会社 ヨシダパッケージ
H9: 伝票 / LOT No.
H11: 発注 / 手配日
G14: 〒212-0055
G15: 神奈川県川崎市幸区南加瀬5-36-6
I16: TEL 044-588-1621
A17: 下記の通り納入願います。 | I17: FAX 044-588-7000
A18: 納期回答をREFAXにてお願い致します。 | I18: 担当 桜 井
A19: 要求No. | B19: P/N 品 名 | H19: 数 量 | I19: 荷姿 | K19: 納期
B21: =VLOOKUP(B20,トレイデータ一覧表!1:1048576,2,FALSE) -> #N/A | I21: =VLOOKUP(B20,トレイデータ一覧表!1:1048576,9,FALSE) -> #N/A | J21: =ROUNDDOWN(H20/I21,0) -> #N/A
B22: 材質 | C22: 厚み | D22: 巾 | E22: 帯電 | F22: ｼﾘｺﾝ | G22: 塗布 | I22: =H20-(I21*J21) -> #N/A | J22: =IF(I22>0,"×1"," ") -> #N/A
B23: =VLOOKUP(B20,トレイデータ一覧表!1:1048576,3,FALSE) -> #N/A | C23: =VLOOKUP(B20,トレイデータ一覧表!1:1048576,4,FALSE) -> #N/A | D23: =VLOOKUP(B20,トレイデータ一覧表!1:1048576,5,FALSE) -> #N/A | E23: =VLOOKUP(B20,トレイデータ一覧表!1:1048576,6,FALSE) -> #N/A | F23: =VLOOKUP(B20,トレイデータ一覧表!1:1048576,7,FALSE) -> #N/A | G23: =VLOOKUP(B20,トレイデータ一覧表!1:1048576,8,FALSE) -> #N/A
A26: 要求No. | B26: P/N 品 名 | H26: 数 量 | I26: 荷姿 | K26: 納期 | P26: =VLOOKUP(B20,トレイデータ一覧表!1:1048576,6,FALSE) -> #N/A
B27: -
B28: =VLOOKUP(B27,トレイデータ一覧表!1:1048576,2,FALSE) -> - | I28: =VLOOKUP(B27,トレイデータ一覧表!1:1048576,9,FALSE) -> - | J28: =ROUNDDOWN(H27/I28,0) -> #VALUE!
B29: 材質 | C29: 厚み | D29: 巾 | E29: 帯電 | F29: ｼﾘｺﾝ | G29: 塗布 | I29: =H27-(I28*J28) -> #VALUE! | J29: =IF(I29>0,"×1"," ") -> #VALUE!
B30: =VLOOKUP(B27,トレイデータ一覧表!1:1048576,3,FALSE) -> - | C30: =VLOOKUP(B27,トレイデータ一覧表!1:1048576,4,FALSE) -> - | D30: =VLOOKUP(B27,トレイデータ一覧表!1:1048576,5,FALSE) -> - | E30: =VLOOKUP(B27,トレイデータ一覧表!1:1048576,6,FALSE) -> - | F30: =VLOOKUP(B27,トレイデータ一覧表!1:1048576,7,FALSE) -> - | G30: =VLOOKUP(B27,トレイデータ一覧表!1:1048576,8,FALSE) -> -
G34: 短手公差
G35: =VLOOKUP(B20,トレイデータ一覧表!1:1048576,20,FALSE) -> #N/A
G36: =VLOOKUP(B20,トレイデータ一覧表!1:1048576,21,FALSE) -> #N/A
B37: 長手公差
B38: =VLOOKUP(B20,トレイデータ一覧表!1:1048576,18,FALSE) -> #N/A
B39: =VLOOKUP(B20,トレイデータ一覧表!1:1048576,19,FALSE) -> #N/A
H41: CUT LINE
I42: =VLOOKUP(B20,トレイデータ一覧表!1:1048576,22,FALSE) -> #N/A | J42: × | K42: =VLOOKUP(B20,トレイデータ一覧表!1:1048576,23,FALSE) -> #N/A
A45: 納品先: | H45: 依頼元：
A46: =VLOOKUP(B45,納入先一覧表!1:1048576,2,FALSE) -> #N/A
A47: =VLOOKUP(B45,納入先一覧表!1:1048576,5,FALSE) -> #N/A | G47: 様
A48: =VLOOKUP(B45,納入先一覧表!1:1048576,3,FALSE) -> #N/A | H48: =VLOOKUP(B45,納入先一覧表!1:1048576,4,FALSE) -> #N/A | K48: 様
A49: ＴＥＬ
A50: =VLOOKUP(B45,納入先一覧表!1:1048576,6,FALSE) -> #N/A

Sheet トレイデータ一覧表
X1: 作成年月日 | Z1: 版 | AA1: 担当 | AB1: 承認
A5: P/N | B5: 型 番 | C5: 材質 | D5: 厚み | E5: ｼｰﾄ巾 | F5: 帯電 | G5: ｼﾘｺﾝ | H5: 塗布 | I5: 入数 | R5: 長手（交差上限） | S5: 長手（交差下限） | T5: 短手（交差上限） | U5: 短手（交差下限） | V5: 長手 | W5: 短手 | X5: 有・無 | Y5: 備 考 | AF5: 指示書作成
A6: AMP | B6: AMP (P試作） | C6: PP(N) | D6: 0.4 | E6: 405 | F6: 有 | G6: 無 | H6: 無
A7: AMP 試作 PS(CL) | B7: 曲げ形状試作PS(CL) | C7: PS(CL) | D7: 0.8 | E7: 405 | F7: 有 | G7: 無 | H7: 無
A8: AMP 試作 A-PET(CL) | B8: 曲げ形状試作A-PET(CL) | C8: A-PET(CL) | D8: 0.8 | E8: 460 | F8: 無 | G8: 有 | H8: 無
A9: 1279334-1 | B9: 1279334-1 (×24) | C9: PVC(CL) | D9: 0.5 | E9: 520 | F9: 有 | G9: 無 | H9: 無 | K9: 354*300 | R9: - | S9: - | T9: - | U9: - | V9: - | W9: - | X9: ○
A10: 1279508-1 | B10: 1279508-1 (×12) | C10: PS(CL) | D10: 0.5 | E10: 520 | F10: 有 | G10: 無 | H10: 無 | I10: 4000 | J10: COVER FOR HMZD CONN.COVER 2PAIR 15.95×100.6 | O10: 385*265 | R10: ±0.3 | S10: - | T10: ±0.3 | U10: - | V10: 99.3 | W10: 15.3 | X10: ○ | Z10: 12面取り | AA10: 別抜き | AB10: 袋詰め
A11: 1279508-2 | B11: 1279508-2 (×12） | C11: PS(CL) | D11: 0.5 | E11: 520 | F11: 有 | G11: 無 | H11: 無 | J11: TRAY FOR HMZD CONN.2PAIR 15.95×125.6 | O11: 385*265 | R11: ±0.3 | S11: - | T11: ±0.3 | U11: - | V11: 124.2 | W11: 15.3 | X11: ○
A12: 1279508-3 | B12: 1279508-3 (×12） | C12: PS(CL) | D12: 0.5 | E12: 520 | F12: 有 | G12: 無 | H12: 無 | I12: 500 | J12: TRAY FOR HMZD CONN.2PAIR 15.95×150.6 | O12: 385*265 | R12: ±0.3 | S12: - | T12: ±0.3 | U12: - | V12: 149.2 | W12: 15.3 | X12: ○
A13: 1279508-4 | B13: 1279508-4 | C13: PS(CL) | D13: 0.5 | E13: 520 | F13: 有 | G13: 無 | H13: 無 | J13: TRAY FOR HMZd CONN COVER 2PAIR1ROW | R13: MAX | T13: MAX | V13: 27.45 | W13: 17.7 | X13: ○ | Z13: 別抜き
A14: 1279508-5 | B14: 1279508-5 | C14: PS(CL) | D14: 0.5 | E14: 520 | F14: 有 | G14: 無 | H14: 無 | J14: TRAY FOR HMZd CONN COVER 2PAIR2ROW | R14: MAX | T14: MAX | V14: 27.45 | W14: 17.7 | X14: ○ | Z14: 別抜き
A15: 1279509-1 | B15: 1279509-1 (×09) | C15: PS(CL) | D15: 0.5 | E15: 520 | F15: 有 | G15: 無 | H15: 無 | I15: 350 | J15: TRAY FOR HMZD CONNCOVER 4PAIR 23.5×163.1 | O15: 385*265 | R15: ±0.3 | S15: - | T15: ±0.3 | U15: - | V15: 161.8 | W15: 23.4 | X15: ○ | Z15: 9面取り | AA15: 別抜き | AB15: 袋詰め
A16: 1279509-2 | B16: 1279509-2 (×09) | C16: PS(CL) | D16: 0.5 | E16: 520 | F16: 有 | G16: 無 | H16: 無 | I16: 350 | J16: COVER FOR HMZD CONN.COVER 2PAIR 23.5×175.6 | O16: 385*265 | R16: ±0.3 | S16: - | T16: ±0.3 | U16: - | V16: 174.1 | W16: 23.4 | X16: ○
A17: 1279509-3 | B17: 1279509-3 (×09) | C17: PS(CL) | D17: 0.5 | E17: 520 | F17: 有 | G17: 無 | H17: 無 | I17: 300 | J17: COVER FOR HMZD CONN.COVER 4PAIR 23.5×200.6 | O17: 385*265 | R17: ±0.3 | S17: - | T17: ±0.3 | U17: - | V17: 199.2 | W17: 23.4 | X17: ○
A18: 1279509-4 | B18: 1279509-4 (×12) | C18: PS(CL) | D18: 0.5 | E18: 520 | F18: 有 | G18: 無 | H18: 無 | I18: 1500 | J18: HMZD CONN.COVER 4PAIR | O18: 385*265 | R18: ±0.5 | T18: ±0.5 | V18: 151.25 | W18: 23.5 | X18: ○
A19: 1279600-1 | B19: 1279600-1 (×14) | C19: PS(CL) | D19: 0.5 | E19: 520 | F19: 有 | G19: 無 | H19: 無 | I19: 1800 | J19: HMZD CONN.COVER 2&3PAIR | N19: 385×265 | R19: ±0.5 | T19: ±0.5 | V19: 126.3 | W19: 20.5 | X19: ○
A20: 1447069-4 | B20: 1447069-4 | C20: PS(N) | D20: 0.4 | E20: 520 | F20: 有 | G20: 無 | H20: 無 | I20: 140 | V20: 367 | W20: 250 | AA20: 別抜き
A21: =ASC(O21) -> 1447287-1 | B21: 1447287-1 | C21: PVC (CL) | D21: 0.5 | E21: 460 | F21: - | G21: - | H21: - | I21: 250 | K21: 354*300 | O21: 1447287-1 | R21: ±1.0 | T21: ±1.0 | V21: 315 | W21: 264 | X21: ○
A22: 1554772-1 | B22: 1554772-1 | C22: PP(N) | D22: 0.4 | E22: 405 | F22: 有 | G22: 無 | H22: 無
A23: 2013973-1 | B23: 2013973-1 | C23: PVC | D23: 0.5 | E23: 460 | F23: 有 | G23: 有 | H23: 無 | K23: 354×300 | R23: ±0.5 | T23: ±0.5 | V23: 90 | W23: 86.3 | X23: ○ | Z23: 9面取り | AA23: 別抜き
A24: AMP-010 | B24: AMP-010 10P | C24: PS(N) | D24: 0.8 | E24: 520 | F24: 有 | G24: 有 | H24: 無 | I24: 140 | K24: 470×300 | R24: ±0.5 | T24: ±0.5 | V24: 428 | W24: 278 | X24: ○
A25: AMP-010-3 | B25: AMP-010-3 | C25: PS(茶) | D25: 0.8 | E25: 520 | F25: 有 | G25: 有 | H25: 無 | I25: 140 | K25: 470×300 | R25: ±0.5 | T25: ±0.5 | V25: 428 | W25: 278 | X25: ○
A26: AMP-011 | B26: AMP-011 3P | C26: PS(N) | D26: 0.8 | E26: 405 | F26: 無 | G26: 有 | H26: 無 | K26: 320×195 | R26: - | S26: - | T26: - | U26: - | V26: - | W26: - | X26: ○
A27: AMP-012 | B27: AMP-012 8P | C27: PS(N) | D27: 0.8 | E27: 520 | F27: 有 | G27: 有 | H27: 無 | I27: 130 | K27: 470×300 | R27: ±0.5 | T27: ±0.5 | V27: 428 | W27: 278 | X27: ○
A28: AMP-012CL | B28: AMP-012 | C28: PS(CL) | D28: 0.8 | E28: 405 | F28: 無 | G28: 無 | H28: 無 | K28: 470*300 | R28: 0 | S28: -2 | T28: 0 | U28: -1 | V28: 461 | W28: 292.5 | X28: ○
A29: AMP-012P | B29: AMP-012 ポケット試作 | X29: ○
A30: AMP-013 | B30: AMP-013 | C30: PS(N) | D30: 0.8 | E30: 520 | F30: 有 | G30: 有 | H30: 無 | I30: 140 | K30: 470×300 | R30: ±1.0 | T30: ±1.0 | V30: 431 | W30: 281 | X30: ○ | AA30: 別抜き
A31: AMP-014 | B31: AMP-014 8P | C31: PP(N) | D31: 0.8 | E31: 520 | F31: 有 | G31: 有 | H31: 無 | I31: 140 | K31: 470×300 | R31: ±0.5 | T31: ±0.5 | V31: 432 | W31: 279 | X31: ○
A32: AMP-015 | B32: AMP-015 12P | C32: PS(N) | D32: 0.8 | E32: 520 | F32: 有 | G32: 有 | H32: 無 | K32: 470×300 | R32: ±1.0 | T32: ±1.0 | V32: 432 | W32: 279 | X32: ○
A33: AMP-016 | B33: AMP-016 8P | C33: PP(N) | D33: 0.8 | E33: 520 | F33: 有 | G33: 無 | H33: 無 | K33: 470×300 | R33: ±0.5 | T33: ±0.5 | V33: 432 | W33: 279 | X33: ○
A34: AMP-016R | B34: AMP-016R 8P | C34: PP(N) | D34: 0.8 | E34: 520 | F34: 有 | G34: 無 | H34: 無 | I34: 130 | K34: 470×300 | R34: ±0.5 | T34: ±0.5 | V34: 432 | W34: 279 | X34: ○
A35: AMP-017 | B35: AMP-017 16P | C35: PP(N) | D35: 0.8 | E35: 520 | F35: 有 | G35: 無 | H35: 無 | K35: 470×300 | R35: ±0.5 | T35: ±0.5 | V35: 432 | W35: 279 | X35: ○
A36: AMP-018 | B36: AMP-018 EPS工程トレイ 6-912143-5 | C36: PP(N) | D36: 0.8 | E36: 520 | F36: 有 | G36: 無 | H36: 無 | I36: 140 | K36: 470×300 | R36: ±0.5 | T36: ±0.5 | V36: 432 | W36: 282 | X36: ○ | AA36: 別抜き
A37: AMP-019 | B37: AMP-019 140P | C37: PP(N) | D37: 0.8 | E37: 520 | F37: 有 | G37: 無 | H37: 無 | I37: 120 | K37: 470×300 | R37: ±0.5 | T37: ±0.5 | V37: 432 | W37: 279 | X37: ○ | AA37: 別抜き
A38: AMP-020 | B38: AMP-020 32P | C38: PS(茶) | D38: 0.8 | E38: 520 | F38: 有 | G38: 有 | H38: 無 | I38: 130 | K38: 470×300 | R38: ±1.0 | T38: ±1.0 | V38: 461 | W38: 292.5 | X38: ○
A39: AMP-021 | B39: AMP-021 16P | C39: PS(N) | D39: 0.8 | E39: 520 | F39: 有 | G39: 有 | H39: 無 | I39: 130 | K39: 470×300 | R39: ±1.0 | T39: ±1.0 | V39: 432 | W39: 279 | X39: ○
A40: AMP-022 | B40: AMP-022 64P | C40: PS(W) | D40: 0.8 | E40: 520 | F40: 有 | G40: 有 | H40: 無 | I40: 120 | K40: 470×300 | R40: ±0.5 | T40: ±0.5 | V40: 461 | W40: 292.5 | X40: ○
A41: AMP-022R | B41: AMP-022R 64P | C41: PS(N) | D41: 0.8 | E41: 520 | F41: 有 | G41: 有 | H41: 無 | I41: 130 | K41: 470×300 | R41: 0 | S41: -2 | T41: 0 | U41: -1 | V41: 461 | W41: 292.5 | X41: ○ | AB41: 袋詰め
A42: AMP-023 | B42: AMP-023 24P | C42: PS(N) | D42: 0.8 | E42: 520 | F42: 有 | G42: 有 | H42: 無 | K42: 470×300 | R42: ±1.0 | T42: ±1.0 | V42: 461 | W42: 292.5 | X42: ○
A43: AMP-024 | B43: AMP-024 20P 6-912127-9 | C43: PP(N) | D43: 1 | E43: 520 | F43: 有 | G43: 無 | H43: 無 | K43: 470×300 | R43: ±0.5 | T43: ±0.5 | V43: 461 | W43: 292.5 | X43: ○ | AA43: 別抜き | AB43: 袋詰め
...

Sheet 納入先一覧表
A1: No. | B1: 送り先 | C1: 住 所 | D1: 依頼元(依頼主) | E1: サ ブ | F1: 電 話 番 号 | G1: FAX
A2: 11 | B2: ＳＭＫ（株）ひたち | C2: * | D2: ＳＭＫ（株） 崎村 | E2: ＦＣ生産技術部 田辺 治雄 | F2: 0293-20-2140
A3: 111 | B3: ＳＭＫ（株） 本社 | C3: * | D3: ＳＭＫ（株） 崎村 | E3: ＦＣ設計 真野 | F3: *
A4: 888 | B4: * | C4: * | D4: * | E4: * | F4: *
A5: 999 | B5: 後日確認 | C5: * | D5: * | E5: * | F5: *
A6: A3C | B6: エースリーシー・デザイン事務所 | C6: 横浜市都筑区荏田南5-21-30 ｼｪﾙみずきが丘203号 | D6: A3C01 | E6: 天野 | F6: 045-948-0434 | G6: 045-948-0454
A7: AAK | B7: （株）アーク RPT工場 | C7: 山梨県富士吉田市小明見4252 | D7: AAK01 | E7: 宮宅 | F7: 0555-23-4325 | G7: 0555-23-9203
A8: AAK1 | B8: （株）アーク | C8: 〒190-0182 東京都西多摩郡日の出町平井22-7 | D8: AAK01 | E8: 量産事業本部 量産事業部 生産Gr. 購買課 | F8: 042-519-9821 | G8: 042-519-9864
A9: AAT | B9: (株)エイアンドティー | C9: 〒252-0816 神奈川県藤沢市遠藤2023-1 | D9: AAT01 1334 | E9: 購買Gr. 湘南ﾁｰﾑ 昆野 様宛 | F9: 0466-86-8682 | G9: 0466-86-8748
A10: AB | B10: (株)エービー | C10: 〒969-0101 福島県西白河郡泉崎村大字泉崎字上狐山2-1 | D10: AB01 1034 | E10: 兼子 様宛 | F10: 0248-53-2043
A11: ACD | B11: (株)エースキャド | C11: 〒155-0032 東京都世田谷区代沢4-27-8 ｸｳｪｽﾄｽｸｴｱ1F | D11: ACD01 1259 | E11: 安東 様宛 | F11: 03-5433-6375 | G11: 03-5433-6375
A12: ACT | B12: (株)アクティ | C12: 〒211-0042 神奈川県川崎市中原区下新城1-11-26 ｹｲ・ﾊｳｽ西館 102号 | D12: ACT01 1702 | E12: 岸田 様 | F12: 044-982-0807 | G12: 044-982-0858
A13: ADK | B13: （株）エーディーケイ | C13: 大田区京浜島2-2-10 | D13: ADK01 | E13: ***** | F13: 03-3790-1565 | G13: 03-3790-0386
A14: AND | B14: (株)ｱﾄﾞﾆｸｽ | C14: 〒193-0931 東京都八王子市台町4-45-15 ｱﾙｶﾃﾞｨｱ西八王子2F | D14: ADN01 1109 | E14: 新家 様宛 | F14: 0426-69-3060 | G14: 0426-69-3061
A15: ADO | B15: アドバンテック 宮古工場 | C15: * | D15: ＳＭＫ（株）杉村 | E15: * | F15: *
A16: ADV | B16: （株）アドバネクス 本社 | C16: * | D16: ADV03 | E16: TTセンター 鈴木 | F16: *
A17: ADV1 | B17: （株）アドバネクス 福島ファクトリー | C17: * | D17: ADV01 | E17: * | F17: 0247-72-6101
A18: ADV2 | B18: （株）アドバネクス 柏崎ファクトリー | C18: 新潟県柏崎市大字藤井字西沖1355 | D18: ADV02 | E18: 猪俣 | F18: 0257-24-2156
A19: ADV3 | B19: （株）アドバネクス 柏崎ファクトリー | C19: 新潟県柏崎市大字藤井字西沖1355 | D19: ADV02 | E19: 第一工場 | F19: 0257-24-2141 | G19: 0257-22-3320
A20: ADV4 | B20: （株）アドバネクス 柏崎ファクトリー | C20: 新潟県柏崎市大字藤井字西沖1355 | D20: ADV02 | E20: ロジスティックス アソシエイツ 田中 | F20: 0257-22-2746 | G20: *
A21: ADV5 | B21: （株）アドバネクス 柏崎ファクトリー | C21: 新潟県柏崎市大字藤井字西沖1355 | D21: ADV02 | E21: * | F21: * | G21: *
A22: ADV6 | B22: （株）アドバネクス 東京ロジスティクスセンター | C22: 東京都荒川区町屋7-6-4 | D22: ADV03 | E22: D2アソシエイツ 井村 | F22: 03-3809-4832 | G22: 03-3809-4839
A23: ADV7 | B23: （株）アドバネクス 柏崎ファクトリー | C23: 新潟県柏崎市大字藤井字西沖1355 | D23: ADV02 | E23: 第三工場 | F23: 0257-24-2141 | G23: 0257-22-6261
A24: ADV8 | B24: （株）アドバネクス 柏崎ファクトリー | C24: 〒945-0193 新潟県柏崎市大字藤井字西沖1287-1 | D24: ADV02 | E24: 第二工場 坂牧 様宛 | F24: 0257-24-2419 | G24: 0257-22-1580
A25: ADV11 | B25: （株）ｱﾄﾞﾊﾞﾝﾃｽﾄﾃﾞｨｰｱｲ | C25: 埼玉県北埼玉郡大利根町新利根1-4-4 | D25: NPC01 | E25: 資材部 購買課 岡安 | F25: 0480-72-7069
A26: AFM | B26: （株）ｴｰｴﾌｴﾑｼｰ | C26: 神奈川県横浜市港北区新羽町165 | D26: AFM01 | E26: 高橋 | F26: 045-532-0041 | G26: 045-532-0091
A27: AGR | B27: (株)アグレス 大阪オフィス | C27: 〒577-0055 大阪府大阪市長栄寺2-12 | D27: AGR01 1831 | E27: 柏口 様宛 | F27: 06-6784-3644 | G27: 06-6787++
A28: AHN | B28: （株）朝比奈 本社 | C28: 町田市成瀬5223 | D28: * | E28: 島田 | F28: 042-722-1901
A29: AHP | B29: (株)アサヒプレシジョン 本社 | C29: 〒949-5411 新潟県長岡市来迎寺1750-1 | D29: AHP01 995 | E29: 製造部 佐藤 様宛 | F29: 0258-92-6440 | G29: 0258-92-6443
A30: AIDK | B30: アイデックス（株） | C30: 秋田県鹿角市十和田山根字上ノ平1番地 | D30: NPC01 | E30: 組立1課 近藤 | F30: 0186-35-5111
A31: AIDS | B31: アイデックス（株） | C31: 秋田県鹿角市十和田山根字上ノ平1番地 | D31: NPC01 | E31: 組立1課 柴田 | F31: 0186-35-5111
A32: AIDY | B32: アイデックス（株） | C32: 秋田県鹿角市十和田山根字上ノ平1番地 | D32: NPC01 | E32: 組立1課 湯沢 | F32: 0186-35-5111
A33: AIH | B33: (有)相原製作所 | C33: 〒343-0115 埼玉県葛飾郡松伏町上赤岩1683-1 | D33: AIH01 1356 | E33: 飯塚 様宛 | F33: 048-991-8984 | G33: 048-991-8985
A34: AIN | B34: (株)ｱｲﾝ | C34: 〒391-0213 長野県茅野市豊平374-2 | D34: AIN01 1033 | E34: 営業部 金丸 様宛 | F34: 0266-72-7165 | G34: 0266-73-5031
A35: AIS | B35: (株)ｱｲｾｽ | C35: 〒018-1512 秋田県南秋田郡井川町北川尻字下田面替場11-1 | D35: AIS01 1136 | E35: 資材 高橋 様宛 | F35: 018-874-3252 | G35: 018-874-3242
A36: AKB | B36: 曙産業(株) | C36: 〒612-8452 京都府京都市伏見区中島堀端町97 | D36: AKB01 1896 | E36: 村上 様 | F36: 075-644-7030 | G36: 075-644-6337
A37: AKH | B37: (株)愛幸発條 | C37: 〒470-0102 愛知県日進市藤島町長塚75-766 | D37: AKH01 1467 | E37: 生産管理部 福井 様宛 | F37: 0561-73-3777 | G37: 0561-73-7538
A38: AKI | B38: (株)エーケイ設計 | C38: 〒411-0822 静岡県三島市松本319-1 ｸﾞﾘｰﾝﾊｲﾂ松本102号 | D38: AKI01 1689 | E38: 近藤 様 | F38: 055-955-7091 | G38: 055-977-7033
A39: AKK | B39: 朝日金属工業（株） | C39: 山形県長井市平山647-3 | D39: ＭＢＳ01 | E39: 開発営業 菅野 | F39: 0238-84-1890
A40: AKK1 | B40: (株)アサカ機工 | C40: 〒352-0011 埼玉県新座市野火止1-10-6 | D40: AKK01 1974 | E40: 仲田 様 | F40: 048-481-2151 | G40: 048-481-2154
...

Sheet 互換性レポート
B1: 成形トレイデータ&指示書（成形）（外注）新071210～.xls の互換性レポート
B2: 2014/5/15 13:03 に実行
B4: このブックで使用されている次の機能は、以前のバージョンの Excel ではサポートされていません。このブックを以前のバージョンの Excel で開くか、以前のファイル形式で保存すると、それらの機能が失われるか、正常に実行されなくなる可能性があります。
B6: 機能の大幅な損失 | E6: 出現数 | F6: バージョン
B8: このオブジェクトに適用されている効果が解除されます。このグラフィックの境界線からはみ出たテキストは表示されません。 | E8: 186
E9: 指示書作成シート(成形）'!A1:V60 | F9: Excel 97-2003
E10: 指示書作成シート（外注）'!A1:V51 | F10: Excel 97-2003
E11: トレイデータ一覧表'!A1:DF6302 | F11: Excel 97-2003
B14: 再現性の低下
B16: 図形、ワードアート、テキスト ボックスなど、このブックのオブジェクトの一部では、オブジェクトの境界を超える長さのテキストを入力できる場合があります。以前のバージョンの Excel では、このオプションに対応していないため、境界を超えたテキストは表示されません。 | E16: 174
E17: トレイデータ一覧表'!A1:DF6302 | F17: Excel 97-2003
